Workbook

Sheet 説明
A1: タイ市場 販売中モデルの発売時期一覧（2026年10月時点）
A3: 作成日 | B3: 46301
A4: 基準日（経過年数の計算） | B4: 46296
A5: 収録モデル数 | B5: =COUNT(モデル一覧!A:A) -> 204
A7: 対象範囲 | B7: 2026年1〜8月の車種別販売ランキング上位200（同期間46台以上）に入る乗用車・ピックアップ・PPV・小型バンを収録した。
B8: 8月以降の新規投入は Lepas L6、Riddara ECON L のみ追加しており、網羅していない。
B9: 小型トラック、超高級スポーツカー、ランキング圏外の少量車種は除外した（ブランド一覧に記載）。
A11: 列の定義 | B11: 車名のタイ初投入（年）：現在のタイ市場名が初めて販売された年。世代ごとに車名を変える車種があるため、MarkLinesの車名との突合に使う。長期使用の車名は空欄。
B12: 現行世代のタイ発売（年・月）：現行世代の価格発表・発売の時期。展示や予約開始のみの時期は採らない。納車開始が大きくずれる場合は「照合上の注意」と備考に記載した。
B13: 経過年数：基準日（B4、変更可）からの経過年。月が不明の場合は7月と仮定した。
B14: 別名：中国名や他市場名。S&Pの車名と突合する際の手がかりとする。
B15: 2026年1〜8月の販売規模：下記出典のランキングに基づく区分。
A17: 確度 | B17: A：本調査で発売時期を報道・メーカー発表により確認（出典URLあり）
B18: B：報道等で概ね確認したが、月や詳細に不確実性が残る
B19: C：一般情報に基づく推定。使用前に照合が必要
A21: 照合上の注意 | B21: 1. タイでは世代交代時に車名を変える例がある（Hilux Vigo→Revo→Travo、Vios→Yaris ATIV、MG4→MG Urban）。MarkLines上は新車名の初登場が世代交代にあたる。
B22: 2. 旧世代と新世代を併売する例がある（Hilux Revo・Travo、Serena C27・C28、MG4・MG Urban）。
B23: 3. 中国系は輸入で投入した後にタイ生産へ切り替える例が多い。S&PのSOPがタイ工場の立ち上げを指す場合、発売より大幅に遅い日付になる。
B24: 4. 発表と納車がずれる例：GWM Ora 5（2026年3月発表→5月納車）、Geely EX2（2025年11月発表→2026年1月以降納車）、Mazda 6e（2026年3月発表→7月納車）。
A26: 主な出典 | B26: 販売規模：Best Selling Cars Blog「Thailand August 2026」（Car250集計） https://bestsellingcarsblog.com/2026/09/thailand-august-2026-bev-most-popular-propulsion-gwm-ora-5-up-to-6/
B27: 発売時期：モデル一覧の出典列（Thairath、motorexpo.co.th、MarkLines、CnEVPost、paultan.org ほか）
A29: シート構成 | B29: モデル一覧：車種ごとの発売時期／ブランド一覧：参入時期と現地生産／突合テンプレート：MarkLines・S&Pとの照合用

Sheet モデル一覧
A1: No. | B1: 系統 | C1: グループ | D1: ブランド | E1: モデル（タイ市場名） | F1: 別名（中国名・他市場名） | G1: 車体 | H1: 動力 | I1: 供給 | J1: 車名のタイ初投入（年） | K1: 現行世代 タイ発売（年） | L1: 現行世代 タイ発売（月） | M1: 前世代 タイ発売（年） | N1: 直近の主な改良・追加 | O1: 現行世代の経過年数 | P1: 車名の経過年数 | Q1: 2026年1〜8月の販売規模 | R1: 照合上の注意 | S1: 確度 | T1: 出典 | U1: 備考
A2: 1 | B2: 日系 | C2: トヨタ | D2: Toyota | E2: Hilux Travo | F2: Hilux（第9世代） | G2: ピックアップ | H2: ディーゼル／BEV（Travo-e） | I2: タイ生産 | J2: 2025 | K2: 2025 | L2: 11 | M2: 2015 | N2: BEV版Travo-eを同時発表 | O2: =IF(K2="","",ROUND((説明!$B$4-DATE(K2,IF(L2="",7,L2),1))/365.25,1)) -> 0.9 | P2: =IF(J2="","",IF(AND(J2=K2,L2<>""),O2,ROUND((説明!$B$4-DATE(J2,7,1))/365.25,1))) -> 0.9 | Q2: 1万台以上（Travo・Revo・Champ合算） | R2: 車名変更型の世代交代／旧世代と併売／合算表記 | S2: A | T2: https://www.motorexpo.co.th/en/news/5258 | U2: 2025年11月10日発表。前世代はHilux Revo。2026年7月のHilux販売の約6割がTravo
A3: 2 | B3: 日系 | C3: トヨタ | D3: Toyota | E3: Hilux Revo | F3: Hilux（第8世代） | G3: ピックアップ | H3: ディーゼル | I3: タイ生産 | J3: 2015 | K3: 2015 | L3: 5 | M3: 2004 | N3: 2020年に大幅改良。Travo発売後も一部仕様を継続販売 | O3: =IF(K3="","",ROUND((説明!$B$4-DATE(K3,IF(L3="",7,L3),1))/365.25,1)) -> 11.4 | P3: =IF(J3="","",IF(AND(J3=K3,L3<>""),O3,ROUND((説明!$B$4-DATE(J3,7,1))/365.25,1))) -> 11.4 | Q3: 1万台以上（同上） | R3: 旧世代と併売／合算表記 | S3: B | T3: — | U3: 前世代はHilux Vigo
A4: 3 | B4: 日系 | C4: トヨタ | D4: Toyota | E4: Hilux Champ | F4: IMV 0系 | G4: ピックアップ（商用） | H4: ディーゼル／ガソリン | I4: タイ生産 | J4: 2023 | K4: 2023 | L4: 11 | M4: （初代） | N4: 2025年8月 ショートホイールベース仕様を追加 | O4: =IF(K4="","",ROUND((説明!$B$4-DATE(K4,IF(L4="",7,L4),1))/365.25,1)) -> 2.9 | P4: =IF(J4="","",IF(AND(J4=K4,L4<>""),O4,ROUND((説明!$B$4-DATE(J4,7,1))/365.25,1))) -> 2.9 | Q4: 1万台以上（同上） | R4: 合算表記 | S4: B | T4: https://www.motorexpo.co.th/en/news/5258 | U4: 廉価ピックアップ
A5: 4 | B5: 日系 | C5: トヨタ | D5: Toyota | E5: Yaris Ativ | F5: Vios（AC100） | G5: セダン | H5: ガソリン／HEV | I5: タイ生産 | J5: 2017 | K5: 2022 | L5: 8 | M5: 2017 | N5: 2025年8月 HEV追加 | O5: =IF(K5="","",ROUND((説明!$B$4-DATE(K5,IF(L5="",7,L5),1))/365.25,1)) -> 4.2 | P5: =IF(J5="","",IF(AND(J5=K5,L5<>""),O5,ROUND((説明!$B$4-DATE(J5,7,1))/365.25,1))) -> 9.3 | Q5: 1万台以上 | R5: 車名変更（旧Vios系の後継） | S5: B | T5: https://www.motorexpo.co.th/en/news/5258 | U5: 第2世代（DNGA）
A6: 5 | B6: 日系 | C6: トヨタ | D6: Toyota | E6: Yaris Cross | F6: Yaris Cross（新興国向け） | G6: SUV | H6: HEV | I6: タイ生産（Gateway工場） | J6: 2023 | K6: 2023 | L6: 10 | M6: （初代） | O6: =IF(K6="","",ROUND((説明!$B$4-DATE(K6,IF(L6="",7,L6),1))/365.25,1)) -> 3 | P6: =IF(J6="","",IF(AND(J6=K6,L6<>""),O6,ROUND((説明!$B$4-DATE(J6,7,1))/365.25,1))) -> 3 | Q6: 1万台以上 | S6: A | T6: https://www.wapcar.my/news/price-equals-up-to-rm-115k-2023-toyota-yaris-cross-launched-in-thailand-15l-hybridonly-tss-74208 | U6: 2023年10月5日発売。タイ仕様はHEVのみ
A7: 6 | B7: 日系 | C7: トヨタ | D7: Toyota | E7: Corolla Cross | G7: SUV | H7: ガソリン／HEV | I7: タイ生産 | J7: 2020 | K7: 2020 | L7: 7 | M7: （初代） | O7: =IF(K7="","",ROUND((説明!$B$4-DATE(K7,IF(L7="",7,L7),1))/365.25,1)) -> 6.3 | P7: =IF(J7="","",IF(AND(J7=K7,L7<>""),O7,ROUND((説明!$B$4-DATE(J7,7,1))/365.25,1))) -> 6.3 | Q7: 1万台以上 | S7: B | T7: — | U7: タイで世界初公開
A8: 7 | B8: 日系 | C8: トヨタ | D8: Toyota | E8: Fortuner | F8: SW4（南米） | G8: PPV | H8: ディーゼル | I8: タイ生産 | J8: 2004 | K8: 2015 | L8: 7 | M8: 2004 | N8: 2020年に大幅改良（Legender追加） | O8: =IF(K8="","",ROUND((説明!$B$4-DATE(K8,IF(L8="",7,L8),1))/365.25,1)) -> 11.3 | P8: =IF(J8="","",IF(AND(J8=K8,L8<>""),O8,ROUND((説明!$B$4-DATE(J8,7,1))/365.25,1))) -> 22.3 | Q8: 5千〜1万台 | S8: B | T8: https://bestsellingcarsblog.com/2015/08/thailand-july-2015-new-toyota-fortuner-and-ford-ranger-land/ | U8: 車名初投入年は要確認
A9: 8 | B9: 日系 | C9: トヨタ | D9: Toyota | E9: Commuter | F9: Hiace系 | G9: バン | H9: ディーゼル | I9: 要確認 | K9: 2019 | O9: =IF(K9="","",ROUND((説明!$B$4-DATE(K9,IF(L9="",7,L9),1))/365.25,1)) -> 7.3 | P9: =IF(J9="","",IF(AND(J9=K9,L9<>""),O9,ROUND((説明!$B$4-DATE(J9,7,1))/365.25,1))) | Q9: 1千〜5千台 | R9: Hiaceとの合算・分離の表記揺れ | S9: C | T9: — | U9: H300系とみられる。2026年からランキングでHiaceと分離表記
A10: 9 | B10: 日系 | C10: トヨタ | D10: Toyota | E10: Camry | F10: Camry（XV80） | G10: セダン | H10: HEV | I10: タイ生産（Gateway工場） | K10: 2024 | L10: 10 | M10: 2018 | O10: =IF(K10="","",ROUND((説明!$B$4-DATE(K10,IF(L10="",7,L10),1))/365.25,1)) -> 2 | P10: =IF(J10="","",IF(AND(J10=K10,L10<>""),O10,ROUND((説明!$B$4-DATE(J10,7,1))/365.25,1))) | Q10: 1千〜5千台 | S10: A | T10: https://autobuzz.my/2024/10/11/all-new-9th-gen-toyota-camry-launched-in-thailand-with-three-variants-from-approx-rm190k/ | U10: 第9世代。車名は長期使用
A11: 10 | B11: 日系 | C11: トヨタ | D11: Toyota | E11: Yaris | F11: Yaris（XP150系エコカー） | G11: ハッチバック | H11: ガソリン | I11: タイ生産 | J11: 2006 | K11: 2013 | L11: 10 | M11: 2006 | N11: 2017年・2020年に改良 | O11: =IF(K11="","",ROUND((説明!$B$4-DATE(K11,IF(L11="",7,L11),1))/365.25,1)) -> 13 | P11: =IF(J11="","",IF(AND(J11=K11,L11<>""),O11,ROUND((説明!$B$4-DATE(J11,7,1))/365.25,1))) -> 20.3 | Q11: 1千〜5千台 | S11: C | T11: — | U11: 世代は要確認
A12: 11 | B12: 日系 | C12: トヨタ | D12: Toyota | E12: Veloz | F12: Avanza Veloz（インドネシア） | G12: MPV | H12: ガソリン | I12: 輸入（インドネシア） | J12: 2022 | K12: 2022 | L12: 2 | O12: =IF(K12="","",ROUND((説明!$B$4-DATE(K12,IF(L12="",7,L12),1))/365.25,1)) -> 4.7 | P12: =IF(J12="","",IF(AND(J12=K12,L12<>""),O12,ROUND((説明!$B$4-DATE(J12,7,1))/365.25,1))) -> 4.7 | Q12: 1千〜5千台 | R12: 車名変更（旧Avanza） | S12: A | T12: https://autobuzz.my/2022/02/24/2022-toyota-veloz-launched-in-thailand-to-replace-ageing-avanza/ | U12: Avanzaの後継
A13: 12 | B13: 日系 | C13: トヨタ | D13: Toyota | E13: Alphard | F13: Alphard（40系） | G13: MPV | H13: HEV | I13: 輸入（日本） | K13: 2023 | L13: 8 | M13: 2015 | O13: =IF(K13="","",ROUND((説明!$B$4-DATE(K13,IF(L13="",7,L13),1))/365.25,1)) -> 3.2 | P13: =IF(J13="","",IF(AND(J13=K13,L13<>""),O13,ROUND((説明!$B$4-DATE(J13,7,1))/365.25,1))) | Q13: 1千〜5千台 | S13: A | T13: https://autobuzz.my/2023/08/17/all-new-toyota-alphard-vellfire-launched-in-thailand-6-seater-boss-carriers-with-2-5-litre-hybrid/ | U13: 第4世代。Vellfireと同時発売
A14: 13 | B14: 日系 | C14: トヨタ | D14: Toyota | E14: Hiace | G14: バン | H14: ディーゼル | I14: 要確認 | K14: 2019 | O14: =IF(K14="","",ROUND((説明!$B$4-DATE(K14,IF(L14="",7,L14),1))/365.25,1)) -> 7.3 | P14: =IF(J14="","",IF(AND(J14=K14,L14<>""),O14,ROUND((説明!$B$4-DATE(J14,7,1))/365.25,1))) | Q14: 1千〜5千台 | R14: Commuterとの合算・分離の表記揺れ | S14: C | T14: — | U14: H300系とみられる
A15: 14 | B15: 日系 | C15: トヨタ | D15: Toyota | E15: Vellfire | G15: MPV | H15: HEV | I15: 輸入（日本） | K15: 2023 | L15: 8 | M15: 2015 | O15: =IF(K15="","",ROUND((説明!$B$4-DATE(K15,IF(L15="",7,L15),1))/365.25,1)) -> 3.2 | P15: =IF(J15="","",IF(AND(J15=K15,L15<>""),O15,ROUND((説明!$B$4-DATE(J15,7,1))/365.25,1))) | Q15: 1千〜5千台 | S15: A | T15: https://autobuzz.my/2023/08/17/all-new-toyota-alphard-vellfire-launched-in-thailand-6-seater-boss-carriers-with-2-5-litre-hybrid/ | U15: Alphardと同時発売
A16: 15 | B16: 日系 | C16: トヨタ | D16: Toyota | E16: Corolla Altis | F16: Corolla（E210） | G16: セダン | H16: ガソリン／HEV | I16: タイ生産 | J16: 2001 | K16: 2019 | L16: 9 | M16: 2014 | O16: =IF(K16="","",ROUND((説明!$B$4-DATE(K16,IF(L16="",7,L16),1))/365.25,1)) -> 7.1 | P16: =IF(J16="","",IF(AND(J16=K16,L16<>""),O16,ROUND((説明!$B$4-DATE(J16,7,1))/365.25,1))) -> 25.3 | Q16: 1千〜5千台 | S16: B | T16: — | U16: 第12世代
A17: 16 | B17: 日系 | C17: トヨタ | D17: Toyota | E17: Land Cruiser FJ | G17: SUV（PPV） | H17: ガソリン | I17: タイ生産（Ban Pho工場） | J17: 2026 | K17: 2026 | L17: 3 | M17: （初代） | O17: =IF(K17="","",ROUND((説明!$B$4-DATE(K17,IF(L17="",7,L17),1))/365.25,1)) -> 0.6 | P17: =IF(J17="","",IF(AND(J17=K17,L17<>""),O17,ROUND((説明!$B$4-DATE(J17,7,1))/365.25,1))) -> 0.6 | Q17: 1千〜5千台 | S17: A | T17: https://en.thairath.co.th/news/auto/2921594 | U17: 2026年3月21日発売。タイが世界初の発売国
A18: 17 | B18: 日系 | C18: トヨタ | D18: Toyota | E18: Innova Zenix | F18: Innova Hycross（インド） | G18: MPV | H18: HEV | I18: 輸入（インドネシア） | J18: 2023 | K18: 2023 | L18: 7 | M18: 2016 | O18: =IF(K18="","",ROUND((説明!$B$4-DATE(K18,IF(L18="",7,L18),1))/365.25,1)) -> 3.3 | P18: =IF(J18="","",IF(AND(J18=K18,L18<>""),O18,ROUND((説明!$B$4-DATE(J18,7,1))/365.25,1))) -> 3.3 | Q18: 1千〜5千台 | R18: 車名変更（旧Innova Crysta） | S18: B | T18: https://Www.wapcar.my/news/after-malaysia-thailand-finally-gets-the-allnew-2023-toyota-innova-zenix-hybrid-only-and-priced-from-rm-185k-70989 | U18: 発売月は報道時期からの推定。ランキング上の表記はInnova
A19: 18 | B19: 日系 | C19: トヨタ | D19: Toyota | E19: bZ4X | G19: SUV | H19: BEV | I19: 輸入（日本） | J19: 2022 | K19: 2022 | L19: 11 | M19: （初代） | N19: 2025年末〜2026年 大幅改良（電池容量拡大） | O19: =IF(K19="","",ROUND((説明!$B$4-DATE(K19,IF(L19="",7,L19),1))/365.25,1)) -> 3.9 | P19: =IF(J19="","",IF(AND(J19=K19,L19<>""),O19,ROUND((説明!$B$4-DATE(J19,7,1))/365.25,1))) -> 3.9 | Q19: 100〜1千台 | R19: 改良後に販売急増 | S19: B | T19: https://carz.com.my/2022/11/toyota-bz4x-ev-exceeds-initial-pre-order-expectations-in-thailand | U19: 2022年11月に予約受付開始。改良の時期は要確認
A20: 19 | B20: 日系 | C20: トヨタ | D20: Toyota | E20: Land Cruiser（300系ほか） | G20: SUV | H20: ガソリン／ディーゼル | I20: 輸入（日本） | K20: 2021 | O20: =IF(K20="","",ROUND((説明!$B$4-DATE(K20,IF(L20="",7,L20),1))/365.25,1)) -> 5.3 | P20: =IF(J20="","",IF(AND(J20=K20,L20<>""),O20,ROUND((説明!$B$4-DATE(J20,7,1))/365.25,1))) | Q20: 100〜1千台 | R20: ランキング表記はLand Cruiser/Prado | S20: C | T20: —
A21: 20 | B21: 日系 | C21: トヨタ | D21: Toyota | E21: Land Cruiser 250 | F21: Land Cruiser Prado | G21: SUV | H21: ディーゼル | I21: 輸入（日本） | K21: 2024 | O21: =IF(K21="","",ROUND((説明!$B$4-DATE(K21,IF(L21="",7,L21),1))/365.25,1)) -> 2.3 | P21: =IF(J21="","",IF(AND(J21=K21,L21<>""),O21,ROUND((説明!$B$4-DATE(J21,7,1))/365.25,1))) | Q21: 100〜1千台 | S21: C | T21: —
A22: 21 | B22: 日系 | C22: トヨタ | D22: Toyota | E22: GR86 | G22: クーペ | H22: ガソリン | I22: 輸入（日本） | K22: 2022 | O22: =IF(K22="","",ROUND((説明!$B$4-DATE(K22,IF(L22="",7,L22),1))/365.25,1)) -> 4.3 | P22: =IF(J22="","",IF(AND(J22=K22,L22<>""),O22,ROUND((説明!$B$4-DATE(J22,7,1))/365.25,1))) | Q22: 100台未満 | S22: C | T22: —
A23: 22 | B23: 日系 | C23: トヨタ | D23: Toyota | E23: GR Yaris | G23: ハッチバック | H23: ガソリン | I23: 輸入（日本） | K23: 2021 | O23: =IF(K23="","",ROUND((説明!$B$4-DATE(K23,IF(L23="",7,L23),1))/365.25,1)) -> 5.3 | P23: =IF(J23="","",IF(AND(J23=K23,L23<>""),O23,ROUND((説明!$B$4-DATE(J23,7,1))/365.25,1))) | Q23: 100台未満 | S23: C | T23: —
A24: 23 | B24: 日系 | C24: トヨタ | D24: Lexus | E24: LM | G24: MPV | H24: HEV | I24: 輸入（日本） | J24: 2020 | K24: 2023 | M24: 2020 | O24: =IF(K24="","",ROUND((説明!$B$4-DATE(K24,IF(L24="",7,L24),1))/365.25,1)) -> 3.3 | P24: =IF(J24="","",IF(AND(J24=K24,L24<>""),O24,ROUND((説明!$B$4-DATE(J24,7,1))/365.25,1))) -> 6.3 | Q24: 100〜1千台 | S24: C | T24: — | U24: 第2世代
A25: 24 | B25: 日系 | C25: トヨタ | D25: Lexus | E25: NX | G25: SUV | H25: HEV／PHEV | I25: 輸入（日本） | K25: 2022 | O25: =IF(K25="","",ROUND((説明!$B$4-DATE(K25,IF(L25="",7,L25),1))/365.25,1)) -> 4.3 | P25: =IF(J25="","",IF(AND(J25=K25,L25<>""),O25,ROUND((説明!$B$4-DATE(J25,7,1))/365.25,1))) | Q25: 100〜1千台 | S25: C | T25: — | U25: 第2世代
A26: 25 | B26: 日系 | C26: トヨタ | D26: Lexus | E26: RX | G26: SUV | H26: HEV | I26: 輸入（日本） | K26: 2023 | O26: =IF(K26="","",ROUND((説明!$B$4-DATE(K26,IF(L26="",7,L26),1))/365.25,1)) -> 3.3 | P26: =IF(J26="","",IF(AND(J26=K26,L26<>""),O26,ROUND((説明!$B$4-DATE(J26,7,1))/365.25,1))) | Q26: 100台未満 | S26: C | T26: — | U26: 第5世代
A27: 26 | B27: 日系 | C27: ホンダ | D27: Honda | E27: City（セダン） | G27: セダン | H27: ガソリン／HEV | I27: タイ生産 | J27: 1996 | K27: 2019 | L27: 11 | M27: 2014 | N27: 2023年に改良 | O27: =IF(K27="","",ROUND((説明!$B$4-DATE(K27,IF(L27="",7,L27),1))/365.25,1)) -> 6.9 | P27: =IF(J27="","",IF(AND(J27=K27,L27<>""),O27,ROUND((説明!$B$4-DATE(J27,7,1))/365.25,1))) -> 30.3 | Q27: 1万台以上（セダン・HB合算） | R27: 合算表記 | S27: B | T27: — | U27: 第7世代。タイで世界初公開
A28: 27 | B28: 日系 | C28: ホンダ | D28: Honda | E28: City Hatchback | G28: ハッチバック | H28: ガソリン／HEV | I28: タイ生産 | J28: 2020 | K28: 2020 | L28: 11 | M28: （初代） | N28: 2023年に改良 | O28: =IF(K28="","",ROUND((説明!$B$4-DATE(K28,IF(L28="",7,L28),1))/365.25,1)) -> 5.9 | P28: =IF(J28="","",IF(AND(J28=K28,L28<>""),O28,ROUND((説明!$B$4-DATE(J28,7,1))/365.25,1))) -> 5.9 | Q28: 1万台以上（同上） | R28: 合算表記 | S28: B | T28: — | U28: Jazzの後継
A29: 28 | B29: 日系 | C29: ホンダ | D29: Honda | E29: HR-V | F29: Vezel（日本） | G29: SUV | H29: HEV | I29: タイ生産 | J29: 2014 | K29: 2021 | L29: 10 | M29: 2014 | O29: =IF(K29="","",ROUND((説明!$B$4-DATE(K29,IF(L29="",7,L29),1))/365.25,1)) -> 5 | P29: =IF(J29="","",IF(AND(J29=K29,L29<>""),O29,ROUND((説明!$B$4-DATE(J29,7,1))/365.25,1))) -> 12.3 | Q29: 1万台以上 | S29: B | T29: — | U29: 第2世代。タイ仕様はHEVのみ
A30: 29 | B30: 日系 | C30: ホンダ | D30: Honda | E30: Civic | G30: セダン | H30: ガソリン／HEV | I30: タイ生産 | K30: 2021 | L30: 8 | M30: 2016 | N30: 2022年6月 e:HEV追加 | O30: =IF(K30="","",ROUND((説明!$B$4-DATE(K30,IF(L30="",7,L30),1))/365.25,1)) -> 5.2 | P30: =IF(J30="","",IF(AND(J30=K30,L30<>""),O30,ROUND((説明!$B$4-DATE(J30,7,1))/365.25,1))) | Q30: 5千〜1万台 | S30: B | T30: — | U30: 第11世代。車名は長期使用
A31: 30 | B31: 日系 | C31: ホンダ | D31: Honda | E31: CR-V | G31: SUV | H31: ガソリン／HEV | I31: タイ生産 | K31: 2023 | L31: 3 | M31: 2017 | O31: =IF(K31="","",ROUND((説明!$B$4-DATE(K31,IF(L31="",7,L31),1))/365.25,1)) -> 3.6 | P31: =IF(J31="","",IF(AND(J31=K31,L31<>""),O31,ROUND((説明!$B$4-DATE(J31,7,1))/365.25,1))) | Q31: 5千〜1万台 | S31: A | T31: https://www.thestorythailand.com/en/?p=94133 | U31: 第6世代。ターボは2023年3月、e:HEVは4月から販売
A32: 31 | B32: 日系 | C32: ホンダ | D32: Honda | E32: Accord | G32: セダン | H32: HEV | I32: タイ生産 | K32: 2023 | L32: 10 | M32: 2019 | N32: 2025年8月改良 | O32: =IF(K32="","",ROUND((説明!$B$4-DATE(K32,IF(L32="",7,L32),1))/365.25,1)) -> 3 | P32: =IF(J32="","",IF(AND(J32=K32,L32<>""),O32,ROUND((説明!$B$4-DATE(J32,7,1))/365.25,1))) | Q32: 1千〜5千台 | S32: B | T32: https://www.topgear.com.ph/news/car-news/honda-accord-thailand-g11-a5100-20231002 | U32: 第11世代。2023年9〜10月に発表・価格公表
A33: 32 | B33: 日系 | C33: ホンダ | D33: Honda | E33: Step WGN | F33: STEP WGN（日本） | G33: MPV | H33: HEV | I33: 輸入（日本） | J33: 2026 | K33: 2026 | L33: 2 | M33: （初代） | O33: =IF(K33="","",ROUND((説明!$B$4-DATE(K33,IF(L33="",7,L33),1))/365.25,1)) -> 0.7 | P33: =IF(J33="","",IF(AND(J33=K33,L33<>""),O33,ROUND((説明!$B$4-DATE(J33,7,1))/365.25,1))) -> 0.7 | Q33: 100〜1千台 | R33: 公開（2025-11）と価格発表（2026-02）にずれ | S33: B | T33: https://paultan.org/2026/03/27/honda-stepwgn-2026-dipamer-di-thailand-varian-spada-hibrid-2-0l-import-dari-jepun-rm216k/ | U33: 2025年11月のモーターエキスポで公開、2026年2月に価格発表
A34: 33 | B34: 日系 | C34: ホンダ | D34: Honda | E34: e:N1 | F34: e:NS1（中国） | G34: SUV | H34: BEV | I34: タイ生産 | J34: 2024 | K34: 2024 | M34: （初代） | O34: =IF(K34="","",ROUND((説明!$B$4-DATE(K34,IF(L34="",7,L34),1))/365.25,1)) -> 2.3 | P34: =IF(J34="","",IF(AND(J34=K34,L34<>""),O34,ROUND((説明!$B$4-DATE(J34,7,1))/365.25,1))) -> 2.3 | Q34: 100〜1千台 | S34: C | T34: — | U34: 発売月は要確認
A35: 34 | B35: 日系 | C35: ホンダ | D35: Honda | E35: e:N2 | F35: e:NS2（中国）／Insight（日本） | G35: SUV | H35: BEV | I35: 輸入（中国） | J35: 2026 | K35: 2026 | L35: 3 | M35: （初代） | O35: =IF(K35="","",ROUND((説明!$B$4-DATE(K35,IF(L35="",7,L35),1))/365.25,1)) -> 0.6 | P35: =IF(J35="","",IF(AND(J35=K35,L35<>""),O35,ROUND((説明!$B$4-DATE(J35,7,1))/365.25,1))) -> 0.6 | Q35: 100台未満 | S35: A | T35: https://www.electrive.com/2026/03/05/honda-to-launch-china-focused-ens2-in-thailand-and-japan/ | U35: 2026年3月のバンコク・モーターショーで発売
A36: 35 | B36: 日系 | C36: いすゞ | D36: Isuzu | E36: D-Max | G36: ピックアップ | H36: ディーゼル | I36: タイ生産 | J36: 2002 | K36: 2019 | L36: 10 | M36: 2011 | N36: 2023年に大幅改良 | O36: =IF(K36="","",ROUND((説明!$B$4-DATE(K36,IF(L36="",7,L36),1))/365.25,1)) -> 7 | P36: =IF(J36="","",IF(AND(J36=K36,L36<>""),O36,ROUND((説明!$B$4-DATE(J36,7,1))/365.25,1))) -> 24.3 | Q36: 1万台以上 | R36: D-Max EVを含む可能性 | S36: B | T36: — | U36: 第3世代
A37: 36 | B37: 日系 | C37: いすゞ | D37: Isuzu | E37: MU-X | G37: PPV | H37: ディーゼル | I37: タイ生産 | J37: 2013 | K37: 2021 | L37: 1 | M37: 2013 | O37: =IF(K37="","",ROUND((説明!$B$4-DATE(K37,IF(L37="",7,L37),1))/365.25,1)) -> 5.7 | P37: =IF(J37="","",IF(AND(J37=K37,L37<>""),O37,ROUND((説明!$B$4-DATE(J37,7,1))/365.25,1))) -> 13.3 | Q37: 5千〜1万台 | S37: B | T37: — | U37: 第2世代
A38: 37 | B38: 日系 | C38: いすゞ | D38: Isuzu | E38: D-Max EV | G38: ピックアップ | H38: BEV | I38: タイ生産 | J38: 2026 | K38: 2026 | L38: 3 | M38: （初代） | O38: =IF(K38="","",ROUND((説明!$B$4-DATE(K38,IF(L38="",7,L38),1))/365.25,1)) -> 0.6 | P38: =IF(J38="","",IF(AND(J38=K38,L38<>""),O38,ROUND((説明!$B$4-DATE(J38,7,1))/365.25,1))) -> 0.6 | Q38: 不明（D-Maxに合算の可能性） | R38: 合算表記の可能性 | S38: A | T38: https://en.thairath.co.th/news/auto/2920545 | U38: 2026年3月17日発売。2025年半ばから欧州向けにタイで生産
A39: 38 | B39: 日系 | C39: 三菱自 | D39: Mitsubishi | E39: Xforce | G39: SUV | H39: HEV | I39: タイ生産（Laem Chabang） | J39: 2025 | K39: 2025 | L39: 3 | M39: （初代） | O39: =IF(K39="","",ROUND((説明!$B$4-DATE(K39,IF(L39="",7,L39),1))/365.25,1)) -> 1.6 | P39: =IF(J39="","",IF(AND(J39=K39,L39<>""),O39,ROUND((説明!$B$4-DATE(J39,7,1))/365.25,1))) -> 1.6 | Q39: 5千〜1万台 | S39: A | T39: https://c.8891.com.tw/news/19900 | U39: タイ仕様はHEV。2025年3月のバンコク・モーターショーで発売
A40: 39 | B40: 日系 | C40: 三菱自 | D40: Mitsubishi | E40: Triton | F40: L200（一部市場） | G40: ピックアップ | H40: ディーゼル | I40: タイ生産 | J40: 2005 | K40: 2023 | L40: 7 | M40: 2014 | O40: =IF(K40="","",ROUND((説明!$B$4-DATE(K40,IF(L40="",7,L40),1))/365.25,1)) -> 3.3 | P40: =IF(J40="","",IF(AND(J40=K40,L40<>""),O40,ROUND((説明!$B$4-DATE(J40,7,1))/365.25,1))) -> 21.3 | Q40: 1千〜5千台 | S40: B | T40: — | U40: 第6世代。タイで世界初公開
...

Sheet ブランド一覧
A1: 系統 | B1: グループ | C1: ブランド | D1: タイでの販売開始（現行体制） | E1: タイ生産・組立 | F1: 2026年1〜8月の販売規模 | G1: 収録車種数 | H1: 出典 | I1: 備考
A2: 日系 | B2: トヨタ | C2: Toyota | D2: 長期 | E2: タイ生産（複数工場） | F2: 1万台以上 | G2: =COUNTIF(モデル一覧!$D:$D,"Toyota") -> 22 | H2: —
A3: 日系 | B3: トヨタ | C3: Lexus | D3: 長期 | E3: 輸入（日本） | F3: 100〜1千台 | G3: =COUNTIF(モデル一覧!$D:$D,"Lexus") -> 3 | H3: — | I3: ランキング圏外の車種（ES等）は未収録
A4: 日系 | B4: ホンダ | C4: Honda | D4: 長期 | E4: タイ生産 | F4: 1万台以上 | G4: =COUNTIF(モデル一覧!$D:$D,"Honda") -> 9 | H4: — | I4: 2026年に中国製EV（e:N2）を輸入投入
A5: 日系 | B5: いすゞ | C5: Isuzu | D5: 長期 | E5: タイ生産 | F5: 1万台以上 | G5: =COUNTIF(モデル一覧!$D:$D,"Isuzu") -> 3 | H5: —
A6: 日系 | B6: 三菱自 | C6: Mitsubishi | D6: 長期 | E6: タイ生産（Laem Chabang） | F6: 1万台以上 | G6: =COUNTIF(モデル一覧!$D:$D,"Mitsubishi") -> 7 | H6: —
A7: 日系 | B7: 日産 | C7: Nissan | D7: 長期 | E7: タイ生産 | F7: 5千〜1万台 | G7: =COUNTIF(モデル一覧!$D:$D,"Nissan") -> 5 | H7: —
A8: 日系 | B8: マツダ | C8: Mazda | D8: 長期 | E8: タイ生産（AutoAlliance Thailand） | F8: 5千〜1万台 | G8: =COUNTIF(モデル一覧!$D:$D,"Mazda") -> 7 | H8: — | I8: 2026年に中国製EV（6e）を輸入投入
A9: 日系 | B9: スズキ | C9: Suzuki | D9: 長期 | E9: タイ生産は2025年末で終了、輸入へ移行 | F9: 1千〜5千台 | G9: =COUNTIF(モデル一覧!$D:$D,"Suzuki") -> 6 | H9: —
A10: 日系 | B10: スバル | C10: Subaru | D10: 長期 | E10: 輸入 | F10: 100〜1千台 | G10: =COUNTIF(モデル一覧!$D:$D,"Subaru") -> 2 | H10: — | I10: 現地組立は終了
A11: 中国系 | B11: BYD | C11: BYD | D11: 2022年10月（販売代理店 Rever Automotive） | E11: タイ生産 2024年7月〜（ラヨーン） | F11: 1万台以上 | G11: =COUNTIF(モデル一覧!$D:$D,"BYD") -> 12 | H11: https://cnevpost.com/2026/07/14/byd-thailand-deliveries-130000-local-plant-2nd-anniversary/
A12: 中国系 | B12: BYD | C12: Denza | D12: 2024年10月 | E12: 輸入 | F12: 100〜1千台 | G12: =COUNTIF(モデル一覧!$D:$D,"Denza") -> 1 | H12: https://carnewschina.com/2024/11/03/byds-denza-officially-entered-thailand-will-launch-denza-d9-premium-mpv/
A13: 中国系 | B13: 奇瑞（Chery） | C13: Omoda & Jaecoo | D13: 2024年3月ブランド発表、8月販売開始 | E13: タイ生産・組立 2025年〜（ラヨーン） | F13: 1万台以上 | G13: =COUNTIF(モデル一覧!$D:$D,"Omoda")+COUNTIF(モデル一覧!$D:$D,"Jaecoo") -> 5 | H13: https://proliance.co.th/?p=1958
A14: 中国系 | B14: 奇瑞（Chery） | C14: Chery | D14: 2025年9月 | E14: タイ組立 2026年〜 | F14: 5千〜1万台 | G14: =COUNTIF(モデル一覧!$D:$D,"Chery") -> 2 | H14: https://www.electrive.com/2026/07/13/thailand-chery-starts-locally-assembling-the-v23/
A15: 中国系 | B15: 奇瑞（Chery） | C15: Lepas | D15: 2026年7月 | E15: 輸入（タイ組立へ移行予定） | F15: 集計外（7月末参入） | G15: =COUNTIF(モデル一覧!$D:$D,"Lepas") -> 1 | H15: https://www.marklines.com/en/news/348181
A16: 中国系 | B16: 上汽（SAIC） | C16: MG（IMを含む） | D16: 2014年（SAIC Motor-CP） | E16: タイ生産（チョンブリ） | F16: 1万台以上 | G16: =COUNTIF(モデル一覧!$D:$D,"MG")+COUNTIF(モデル一覧!$D:$D,"IM（MGが販売）") -> 15 | H16: —
A17: 中国系 | B17: 長城（GWM） | C17: GWM（Haval・Ora・Tank・Wey・Poer） | D17: 2021年2月 | E17: タイ生産 2021年6月〜（ラヨーン、旧GM工場） | F17: 1万台以上 | G17: =COUNTIF(モデル一覧!$D:$D,"GWM（Haval）")+COUNTIF(モデル一覧!$D:$D,"GWM（Ora）")+COUNTIF(モデル一覧!$D:$D,"GWM（Tank）")+COUNTIF(モデル一覧!$D:$D,"GWM（Wey）")+COUNTIF(モデル一覧!$D:$D,"GWM（Poer）") -> 8 | H17: https://cnevpost.com/2021/10/19/great-wall-motor-says-ora-good-cat-gets-over-6000-orders-within-48-hours-of-pre-sale-in-thailand | I17: Poerは販売統計上で別ブランド表記
A18: 中国系 | B18: 広汽（GAC） | C18: GAC Aion（Hyptec・GACを含む） | D18: 2023年9月 | E18: タイ生産 2024年7月〜（ラヨーン） | F18: 1万台以上 | G18: =COUNTIF(モデル一覧!$D:$D,"GAC Aion")+COUNTIF(モデル一覧!$D:$D,"GAC") -> 6 | H18: https://autonews.gasgoo.com/china_news/70035792.html
A19: 中国系 | B19: 吉利（Geely） | C19: Geely | D19: 2024年11月（Thonburi Group） | E19: 輸入（中国） | F19: 1万台以上 | G19: =COUNTIF(モデル一覧!$D:$D,"Geely") -> 2 | H19: https://wapcar.my/news/geely-breaking-its-promise-to-make-malaysia-its-rhd-hub-launches-chinamade-geely-ex5-in-thailand-83033
A20: 中国系 | B20: 吉利（Geely） | C20: Zeekr | D20: 2024年3月 | E20: 輸入（中国） | F20: 1千〜5千台 | G20: =COUNTIF(モデル一覧!$D:$D,"Zeekr") -> 3 | H20: https://cnevpost.com/2025/08/19/zeekr-launches-7x-thailand/
A21: 中国系 | B21: 吉利（Geely） | C21: Riddara | D21: 2024年11月 | E21: 輸入（中国） | F21: 1千〜5千台 | G21: =COUNTIF(モデル一覧!$D:$D,"Riddara") -> 3 | H21: https://autobuzz.my/2024/11/01/land-of-smiles-gets-its-first-electric-pickup-truck-with-the-launch-of-the-riddara-rd6-in-thailand/
A22: 中国系 | B22: 長安（Changan） | C22: Deepal | D22: 2023年11月 | E22: タイ生産 2025年〜（ラヨーン） | F22: 1万台以上 | G22: =COUNTIF(モデル一覧!$D:$D,"Deepal") -> 4 | H22: https://cnevpost.com/2023/11/30/deepal-starts-selling-2-ev-models-thailand/
A23: 中国系 | B23: 長安（Changan） | C23: Changan | D23: 2023年11月（ブランド発表） | E23: タイ生産（ラヨーン） | F23: 1千〜5千台 | G23: =COUNTIF(モデル一覧!$D:$D,"Changan") -> 2 | H23: https://carnewschina.com/2026/05/29/changans-atto-2-rival-nevo-q05-launches-in-thailand-starting-from-19400-usd/ | I23: 販売統計上は2026年から別ブランド表記
A24: 中国系 | B24: 長安（Changan） | C24: Avatr | D24: 2024年9月 | E24: Avatr 11はタイ生産 | F24: 100〜1千台 | G24: =COUNTIF(モデル一覧!$D:$D,"Avatr") -> 2 | H24: https://cnevpost.com/2026/01/28/avatr-rolls-off-1st-right-hand-drive-07-suvs/
A25: 中国系 | B25: 小鵬（Xpeng） | C25: Xpeng | D25: 2024年3月 | E25: 輸入（中国） | F25: 1千〜5千台 | G25: =COUNTIF(モデル一覧!$D:$D,"Xpeng") -> 2 | H25: https://paultan.org/tags/xpeng-g9
A26: 中国系 | B26: 零跑（Leapmotor） | C26: Leapmotor | D26: 2025年（要確認） | E26: 輸入（中国） | F26: 100〜1千台 | G26: =COUNTIF(モデル一覧!$D:$D,"Leapmotor") -> 2 | H26: —
A27: 中国系 | B27: 上汽通用五菱（SGMW） | C27: Wuling | D27: 2023年（要確認） | E27: タイ組立あり（Laem Chabang） | F27: 1千〜5千台 | G27: =COUNTIF(モデル一覧!$D:$D,"Wuling") -> 4 | H27: —
A28: 中国系 | B28: 合衆（Hozon） | C28: Neta | D28: 2022年 | E28: タイ組立（要確認） | F28: 100〜1千台 | G28: =COUNTIF(モデル一覧!$D:$D,"Neta") -> 1 | H28: — | I28: 本国の経営悪化で販売急減
A29: 韓国系 | B29: 現代自 | C29: Hyundai | D29: 長期 | E29: 輸入中心（Ioniq 5はタイ組立） | F29: 1千〜5千台 | G29: =COUNTIF(モデル一覧!$D:$D,"Hyundai") -> 6 | H29: —
A30: 韓国系 | B30: 起亜 | C30: Kia | D30: 長期 | E30: 輸入 | F30: 1千〜5千台 | G30: =COUNTIF(モデル一覧!$D:$D,"Kia") -> 4 | H30: —
A31: 米国系 | B31: フォード | C31: Ford | D31: 長期 | E31: タイ生産（ラヨーン） | F31: 1万台以上 | G31: =COUNTIF(モデル一覧!$D:$D,"Ford") -> 3 | H31: —
A32: 米国系 | B32: テスラ | C32: Tesla | D32: 2022年12月 | E32: 輸入（中国） | F32: 5千〜1万台 | G32: =COUNTIF(モデル一覧!$D:$D,"Tesla") -> 2 | H32: —
A33: 欧州系 | B33: メルセデス・ベンツ | C33: Mercedes-Benz | D33: 長期 | E33: 一部タイ組立 | F33: 1千〜5千台 | G33: =COUNTIF(モデル一覧!$D:$D,"Mercedes-Benz") -> 17 | H33: —
A34: 欧州系 | B34: BMW | C34: BMW | D34: 長期 | E34: 一部タイ組立（ラヨーン） | F34: 5千〜1万台 | G34: =COUNTIF(モデル一覧!$D:$D,"BMW") -> 16 | H34: —
A35: 欧州系 | B35: BMW | C35: MINI | D35: 長期 | E35: 輸入 | F35: 1千〜5千台 | G35: =COUNTIF(モデル一覧!$D:$D,"MINI") -> 3 | H35: —
A36: 欧州系 | B36: 吉利（Volvo Cars） | C36: Volvo | D36: 長期 | E36: 一部タイ組立 | F36: 1千〜5千台 | G36: =COUNTIF(モデル一覧!$D:$D,"Volvo") -> 6 | H36: — | I36: 吉利傘下の欧州ブランド
A37: 欧州系 | B37: フォルクスワーゲン | C37: Porsche | D37: 長期 | E37: 一部タイ組立 | F37: 1千〜5千台 | G37: =COUNTIF(モデル一覧!$D:$D,"Porsche") -> 6 | H37: —
A38: 欧州系 | B38: フォルクスワーゲン | C38: Audi | D38: 長期 | E38: 輸入 | F38: 100〜1千台 | G38: =COUNTIF(モデル一覧!$D:$D,"Audi") -> 2 | H38: —
A39: 中国系 | B39: 蔚来（NIO） | C39: NIO（Firefly） | D39: 2026年3月 | E39: 輸入（中国） | F39: 100台未満 | G39: 0 | H39: — | I39: 収録外（ランキング圏外）
A40: 欧州系 | B40: — | C40: Land Rover・Peugeot・Jeep・Volkswagen | D40: 長期 | E40: 輸入 | F40: 100台未満 | G40: 0 | H40: — | I40: 収録外（少量）
...

Sheet 突合テンプレート
A1: MarkLines × S&P 突合テンプレート
A2: 灰色の列に入力し、白の列は自動計算とする。日付は各月1日で入力する（例：2024/08/01）。モデルIDはモデル一覧のNo.。6行目は記入例（日付は架空の値）で、使用時は上書きか削除する。
A3: 判定の目安：差が±3か月以内なら整合。S&Pが3か月超早い場合はSOP・生産国工場基準・世代違いを、MarkLinesが早い場合は旧世代を含む車名対応や少量の先行登録を確認する。
A5: MarkLines車種名 | B5: S&P車名 | C5: S&P世代・プログラム | D5: モデルID | E5: 対応タイプ | F5: MarkLines 継続販売開始月 | G5: S&P日付 | H5: S&P日付の種類 | I5: 本表のブランド | J5: 本表のモデル | K5: 本表の現行世代発売 | L5: 差（ML−S&P、月） | M5: 差（ML−本表、月） | N5: 判定 | O5: 採用t0 | P5: 採用根拠
A6: （例）Yaris ATIV | B6: （例）Vios | C6: （例）第4世代 | D6: 4 | E6: 1対1 | F6: 44805 | G6: 44713 | H6: SOP（タイ工場） | I6: =IF($D6="","",IFERROR(INDEX(モデル一覧!$D:$D,MATCH($D6,モデル一覧!$A:$A,0)),"IDなし")) -> Toyota | J6: =IF($D6="","",IFERROR(INDEX(モデル一覧!$E:$E,MATCH($D6,モデル一覧!$A:$A,0)),"IDなし")) -> Yaris Ativ | K6: =IF($D6="","",IFERROR(IF(INDEX(モデル一覧!$L:$L,MATCH($D6,モデル一覧!$A:$A,0))="","",DATE(INDEX(モデル一覧!$K:$K,MATCH($D6,モデル一覧!$A:$A,0)),INDEX(モデル一覧!$L:$L,MATCH($D6,モデル一覧!$A:$A,0)),1)),"")) -> 44774 | L6: =IF(OR($F6="",$G6=""),"",(YEAR($F6)-YEAR($G6))*12+MONTH($F6)-MONTH($G6)) -> 3 | M6: =IF(OR($F6="",$K6=""),"",(YEAR($F6)-YEAR($K6))*12+MONTH($F6)-MONTH($K6)) -> 1 | N6: =IF($L6="","",IF(ABS($L6)<=3,"整合",IF($L6>3,"S&P先行：SOP・生産国・世代を確認","ML先行：旧世代込み・先行登録を確認"))) -> 整合 | O6: 44774 | P6: （例）差が3か月以内のため本表の発売月を採用
I7: =IF($D7="","",IFERROR(INDEX(モデル一覧!$D:$D,MATCH($D7,モデル一覧!$A:$A,0)),"IDなし")) | J7: =IF($D7="","",IFERROR(INDEX(モデル一覧!$E:$E,MATCH($D7,モデル一覧!$A:$A,0)),"IDなし")) | K7: =IF($D7="","",IFERROR(IF(INDEX(モデル一覧!$L:$L,MATCH($D7,モデル一覧!$A:$A,0))="","",DATE(INDEX(モデル一覧!$K:$K,MATCH($D7,モデル一覧!$A:$A,0)),INDEX(モデル一覧!$L:$L,MATCH($D7,モデル一覧!$A:$A,0)),1)),"")) | L7: =IF(OR($F7="",$G7=""),"",(YEAR($F7)-YEAR($G7))*12+MONTH($F7)-MONTH($G7)) | M7: =IF(OR($F7="",$K7=""),"",(YEAR($F7)-YEAR($K7))*12+MONTH($F7)-MONTH($K7)) | N7: =IF($L7="","",IF(ABS($L7)<=3,"整合",IF($L7>3,"S&P先行：SOP・生産国・世代を確認","ML先行：旧世代込み・先行登録を確認")))
I8: =IF($D8="","",IFERROR(INDEX(モデル一覧!$D:$D,MATCH($D8,モデル一覧!$A:$A,0)),"IDなし")) | J8: =IF($D8="","",IFERROR(INDEX(モデル一覧!$E:$E,MATCH($D8,モデル一覧!$A:$A,0)),"IDなし")) | K8: =IF($D8="","",IFERROR(IF(INDEX(モデル一覧!$L:$L,MATCH($D8,モデル一覧!$A:$A,0))="","",DATE(INDEX(モデル一覧!$K:$K,MATCH($D8,モデル一覧!$A:$A,0)),INDEX(モデル一覧!$L:$L,MATCH($D8,モデル一覧!$A:$A,0)),1)),"")) | L8: =IF(OR($F8="",$G8=""),"",(YEAR($F8)-YEAR($G8))*12+MONTH($F8)-MONTH($G8)) | M8: =IF(OR($F8="",$K8=""),"",(YEAR($F8)-YEAR($K8))*12+MONTH($F8)-MONTH($K8)) | N8: =IF($L8="","",IF(ABS($L8)<=3,"整合",IF($L8>3,"S&P先行：SOP・生産国・世代を確認","ML先行：旧世代込み・先行登録を確認")))
I9: =IF($D9="","",IFERROR(INDEX(モデル一覧!$D:$D,MATCH($D9,モデル一覧!$A:$A,0)),"IDなし")) | J9: =IF($D9="","",IFERROR(INDEX(モデル一覧!$E:$E,MATCH($D9,モデル一覧!$A:$A,0)),"IDなし")) | K9: =IF($D9="","",IFERROR(IF(INDEX(モデル一覧!$L:$L,MATCH($D9,モデル一覧!$A:$A,0))="","",DATE(INDEX(モデル一覧!$K:$K,MATCH($D9,モデル一覧!$A:$A,0)),INDEX(モデル一覧!$L:$L,MATCH($D9,モデル一覧!$A:$A,0)),1)),"")) | L9: =IF(OR($F9="",$G9=""),"",(YEAR($F9)-YEAR($G9))*12+MONTH($F9)-MONTH($G9)) | M9: =IF(OR($F9="",$K9=""),"",(YEAR($F9)-YEAR($K9))*12+MONTH($F9)-MONTH($K9)) | N9: =IF($L9="","",IF(ABS($L9)<=3,"整合",IF($L9>3,"S&P先行：SOP・生産国・世代を確認","ML先行：旧世代込み・先行登録を確認")))
I10: =IF($D10="","",IFERROR(INDEX(モデル一覧!$D:$D,MATCH($D10,モデル一覧!$A:$A,0)),"IDなし")) | J10: =IF($D10="","",IFERROR(INDEX(モデル一覧!$E:$E,MATCH($D10,モデル一覧!$A:$A,0)),"IDなし")) | K10: =IF($D10="","",IFERROR(IF(INDEX(モデル一覧!$L:$L,MATCH($D10,モデル一覧!$A:$A,0))="","",DATE(INDEX(モデル一覧!$K:$K,MATCH($D10,モデル一覧!$A:$A,0)),INDEX(モデル一覧!$L:$L,MATCH($D10,モデル一覧!$A:$A,0)),1)),"")) | L10: =IF(OR($F10="",$G10=""),"",(YEAR($F10)-YEAR($G10))*12+MONTH($F10)-MONTH($G10)) | M10: =IF(OR($F10="",$K10=""),"",(YEAR($F10)-YEAR($K10))*12+MONTH($F10)-MONTH($K10)) | N10: =IF($L10="","",IF(ABS($L10)<=3,"整合",IF($L10>3,"S&P先行：SOP・生産国・世代を確認","ML先行：旧世代込み・先行登録を確認")))
I11: =IF($D11="","",IFERROR(INDEX(モデル一覧!$D:$D,MATCH($D11,モデル一覧!$A:$A,0)),"IDなし")) | J11: =IF($D11="","",IFERROR(INDEX(モデル一覧!$E:$E,MATCH($D11,モデル一覧!$A:$A,0)),"IDなし")) | K11: =IF($D11="","",IFERROR(IF(INDEX(モデル一覧!$L:$L,MATCH($D11,モデル一覧!$A:$A,0))="","",DATE(INDEX(モデル一覧!$K:$K,MATCH($D11,モデル一覧!$A:$A,0)),INDEX(モデル一覧!$L:$L,MATCH($D11,モデル一覧!$A:$A,0)),1)),"")) | L11: =IF(OR($F11="",$G11=""),"",(YEAR($F11)-YEAR($G11))*12+MONTH($F11)-MONTH($G11)) | M11: =IF(OR($F11="",$K11=""),"",(YEAR($F11)-YEAR($K11))*12+MONTH($F11)-MONTH($K11)) | N11: =IF($L11="","",IF(ABS($L11)<=3,"整合",IF($L11>3,"S&P先行：SOP・生産国・世代を確認","ML先行：旧世代込み・先行登録を確認")))
I12: =IF($D12="","",IFERROR(INDEX(モデル一覧!$D:$D,MATCH($D12,モデル一覧!$A:$A,0)),"IDなし")) | J12: =IF($D12="","",IFERROR(INDEX(モデル一覧!$E:$E,MATCH($D12,モデル一覧!$A:$A,0)),"IDなし")) | K12: =IF($D12="","",IFERROR(IF(INDEX(モデル一覧!$L:$L,MATCH($D12,モデル一覧!$A:$A,0))="","",DATE(INDEX(モデル一覧!$K:$K,MATCH($D12,モデル一覧!$A:$A,0)),INDEX(モデル一覧!$L:$L,MATCH($D12,モデル一覧!$A:$A,0)),1)),"")) | L12: =IF(OR($F12="",$G12=""),"",(YEAR($F12)-YEAR($G12))*12+MONTH($F12)-MONTH($G12)) | M12: =IF(OR($F12="",$K12=""),"",(YEAR($F12)-YEAR($K12))*12+MONTH($F12)-MONTH($K12)) | N12: =IF($L12="","",IF(ABS($L12)<=3,"整合",IF($L12>3,"S&P先行：SOP・生産国・世代を確認","ML先行：旧世代込み・先行登録を確認")))
I13: =IF($D13="","",IFERROR(INDEX(モデル一覧!$D:$D,MATCH($D13,モデル一覧!$A:$A,0)),"IDなし")) | J13: =IF($D13="","",IFERROR(INDEX(モデル一覧!$E:$E,MATCH($D13,モデル一覧!$A:$A,0)),"IDなし")) | K13: =IF($D13="","",IFERROR(IF(INDEX(モデル一覧!$L:$L,MATCH($D13,モデル一覧!$A:$A,0))="","",DATE(INDEX(モデル一覧!$K:$K,MATCH($D13,モデル一覧!$A:$A,0)),INDEX(モデル一覧!$L:$L,MATCH($D13,モデル一覧!$A:$A,0)),1)),"")) | L13: =IF(OR($F13="",$G13=""),"",(YEAR($F13)-YEAR($G13))*12+MONTH($F13)-MONTH($G13)) | M13: =IF(OR($F13="",$K13=""),"",(YEAR($F13)-YEAR($K13))*12+MONTH($F13)-MONTH($K13)) | N13: =IF($L13="","",IF(ABS($L13)<=3,"整合",IF($L13>3,"S&P先行：SOP・生産国・世代を確認","ML先行：旧世代込み・先行登録を確認")))
I14: =IF($D14="","",IFERROR(INDEX(モデル一覧!$D:$D,MATCH($D14,モデル一覧!$A:$A,0)),"IDなし")) | J14: =IF($D14="","",IFERROR(INDEX(モデル一覧!$E:$E,MATCH($D14,モデル一覧!$A:$A,0)),"IDなし")) | K14: =IF($D14="","",IFERROR(IF(INDEX(モデル一覧!$L:$L,MATCH($D14,モデル一覧!$A:$A,0))="","",DATE(INDEX(モデル一覧!$K:$K,MATCH($D14,モデル一覧!$A:$A,0)),INDEX(モデル一覧!$L:$L,MATCH($D14,モデル一覧!$A:$A,0)),1)),"")) | L14: =IF(OR($F14="",$G14=""),"",(YEAR($F14)-YEAR($G14))*12+MONTH($F14)-MONTH($G14)) | M14: =IF(OR($F14="",$K14=""),"",(YEAR($F14)-YEAR($K14))*12+MONTH($F14)-MONTH($K14)) | N14: =IF($L14="","",IF(ABS($L14)<=3,"整合",IF($L14>3,"S&P先行：SOP・生産国・世代を確認","ML先行：旧世代込み・先行登録を確認")))
I15: =IF($D15="","",IFERROR(INDEX(モデル一覧!$D:$D,MATCH($D15,モデル一覧!$A:$A,0)),"IDなし")) | J15: =IF($D15="","",IFERROR(INDEX(モデル一覧!$E:$E,MATCH($D15,モデル一覧!$A:$A,0)),"IDなし")) | K15: =IF($D15="","",IFERROR(IF(INDEX(モデル一覧!$L:$L,MATCH($D15,モデル一覧!$A:$A,0))="","",DATE(INDEX(モデル一覧!$K:$K,MATCH($D15,モデル一覧!$A:$A,0)),INDEX(モデル一覧!$L:$L,MATCH($D15,モデル一覧!$A:$A,0)),1)),"")) | L15: =IF(OR($F15="",$G15=""),"",(YEAR($F15)-YEAR($G15))*12+MONTH($F15)-MONTH($G15)) | M15: =IF(OR($F15="",$K15=""),"",(YEAR($F15)-YEAR($K15))*12+MONTH($F15)-MONTH($K15)) | N15: =IF($L15="","",IF(ABS($L15)<=3,"整合",IF($L15>3,"S&P先行：SOP・生産国・世代を確認","ML先行：旧世代込み・先行登録を確認")))
I16: =IF($D16="","",IFERROR(INDEX(モデル一覧!$D:$D,MATCH($D16,モデル一覧!$A:$A,0)),"IDなし")) | J16: =IF($D16="","",IFERROR(INDEX(モデル一覧!$E:$E,MATCH($D16,モデル一覧!$A:$A,0)),"IDなし")) | K16: =IF($D16="","",IFERROR(IF(INDEX(モデル一覧!$L:$L,MATCH($D16,モデル一覧!$A:$A,0))="","",DATE(INDEX(モデル一覧!$K:$K,MATCH($D16,モデル一覧!$A:$A,0)),INDEX(モデル一覧!$L:$L,MATCH($D16,モデル一覧!$A:$A,0)),1)),"")) | L16: =IF(OR($F16="",$G16=""),"",(YEAR($F16)-YEAR($G16))*12+MONTH($F16)-MONTH($G16)) | M16: =IF(OR($F16="",$K16=""),"",(YEAR($F16)-YEAR($K16))*12+MONTH($F16)-MONTH($K16)) | N16: =IF($L16="","",IF(ABS($L16)<=3,"整合",IF($L16>3,"S&P先行：SOP・生産国・世代を確認","ML先行：旧世代込み・先行登録を確認")))
I17: =IF($D17="","",IFERROR(INDEX(モデル一覧!$D:$D,MATCH($D17,モデル一覧!$A:$A,0)),"IDなし")) | J17: =IF($D17="","",IFERROR(INDEX(モデル一覧!$E:$E,MATCH($D17,モデル一覧!$A:$A,0)),"IDなし")) | K17: =IF($D17="","",IFERROR(IF(INDEX(モデル一覧!$L:$L,MATCH($D17,モデル一覧!$A:$A,0))="","",DATE(INDEX(モデル一覧!$K:$K,MATCH($D17,モデル一覧!$A:$A,0)),INDEX(モデル一覧!$L:$L,MATCH($D17,モデル一覧!$A:$A,0)),1)),"")) | L17: =IF(OR($F17="",$G17=""),"",(YEAR($F17)-YEAR($G17))*12+MONTH($F17)-MONTH($G17)) | M17: =IF(OR($F17="",$K17=""),"",(YEAR($F17)-YEAR($K17))*12+MONTH($F17)-MONTH($K17)) | N17: =IF($L17="","",IF(ABS($L17)<=3,"整合",IF($L17>3,"S&P先行：SOP・生産国・世代を確認","ML先行：旧世代込み・先行登録を確認")))
I18: =IF($D18="","",IFERROR(INDEX(モデル一覧!$D:$D,MATCH($D18,モデル一覧!$A:$A,0)),"IDなし")) | J18: =IF($D18="","",IFERROR(INDEX(モデル一覧!$E:$E,MATCH($D18,モデル一覧!$A:$A,0)),"IDなし")) | K18: =IF($D18="","",IFERROR(IF(INDEX(モデル一覧!$L:$L,MATCH($D18,モデル一覧!$A:$A,0))="","",DATE(INDEX(モデル一覧!$K:$K,MATCH($D18,モデル一覧!$A:$A,0)),INDEX(モデル一覧!$L:$L,MATCH($D18,モデル一覧!$A:$A,0)),1)),"")) | L18: =IF(OR($F18="",$G18=""),"",(YEAR($F18)-YEAR($G18))*12+MONTH($F18)-MONTH($G18)) | M18: =IF(OR($F18="",$K18=""),"",(YEAR($F18)-YEAR($K18))*12+MONTH($F18)-MONTH($K18)) | N18: =IF($L18="","",IF(ABS($L18)<=3,"整合",IF($L18>3,"S&P先行：SOP・生産国・世代を確認","ML先行：旧世代込み・先行登録を確認")))
... I305: =IF($D305="","",IFERROR(INDEX(モデル一覧!$D:$D,MATCH($D305,モデル一覧!$A:$A,0)),"IDなし")) | J305: =IF($D305="","",IFERROR(INDEX(モデル一覧!$E:$E,MATCH($D305,モデル一覧!$A:$A,0)),"IDなし")) | K305: =IF($D305="","",IFERROR(IF(INDEX(モデル一覧!$L:$L,MATCH($D305,モデル一覧!$A:$A,0))="","",DATE(INDEX(モデル一覧!$K:$K,MATCH($D305,モデル一覧!$A:$A,0)),INDEX(モデル一覧!$L:$L,MATCH($D305,モデル一覧!$A:$A,0)),1)),"")) | L305: =IF(OR($F305="",$G305=""),"",(YEAR($F305)-YEAR($G305))*12+MONTH($F305)-MONTH($G305)) | M305: =IF(OR($F305="",$K305=""),"",(YEAR($F305)-YEAR($K305))*12+MONTH($F305)-MONTH($K305)) | N305: =IF($L305="","",IF(ABS($L305)<=3,"整合",IF($L305>3,"S&P先行：SOP・生産国・世代を確認","ML先行：旧世代込み・先行登録を確認")))
